Workbook

Sheet README
A1: International Tax Competitiveness Index — Working Excel Calculator
A3: Replicates the Tax Foundation's ITCI scoring methodology (github.com/TaxFoundation/international-tax-competitiveness-index, R_code_files/08_index_calculations.R) as live, formula-driven Excel sheets — no VBA, no add-ins. Entirely closed-form (z-scores, averages, min/max rescale); no eigen-decomposition or iterative engine needed anywhere.
A5: Color legend
A6: Amber cells = GIVEN (2025 ITCI input data, from the Tax Foundation's own repo)
A7: Teal cells = LIVE (formulas; recalculate automatically)
A9: Validated
A10: Every stage (subcategories, categories, final score) matches the Tax Foundation's own real 2025 ground-truth output files to floating-point precision (<1e-13) for all 38 countries — see itci_core.py and scratch/validate.py in the companion Python project. Two real bugs were caught and fixed during validation: (1) corporate_other_rev/personal_other_rev need ABS() before z-scoring (Sweden has a negative personal_other_rev, off by 0.33/100 without the fix), and (2) categories must be computed from the RAW (pre-rescale) subcategory z-averages, not the rescaled 0-100 subcategory values — confirmed empirically against categories_score.csv since the R script reuses one variable name for both versions, making it ambiguous from the code alone.
A12: Pipeline
A13: 1. ZScores: z = (x-AVERAGE)/STDEV across the 38-country cross-section, per variable. corporate_other_rev/personal_other_rev use ABS(x) first. 30 "higher=worse" variables (rates, surtaxes, withholding taxes, restrictive rules) then multiplied by -1.
A14: 2. Subcategories: equal-weighted average of the relevant z-scores, one column per subcategory (15 total).
A15: 3. SubcategoriesScored: score2() rescale — shift so MIN becomes 1, scale so MAX becomes 100 — applied independently to each subcategory.
A16: 4. Categories: equal-weighted average of the RAW (pre-score2) subcategory scores, one column per category (5 total: corporate, consumption, property, income, cross_border).
... A21: Overwrite the amber GIVEN cells on RawData with updated variable values (same 38 countries, or add/remove rows). Everything downstream — z-scores, subcategories, categories, final score, ranks, chart — recalculates automatically. This is exactly how the Tax Foundation's own repo supports testing tax-reform scenarios (README: "modify tax variables ... re-run ... compare against baseline").

Sheet RawData
A1: Raw Data (GIVEN) — 38 countries x 42 variables, 2025 ITCI input data
A2: country | B2: corporate_rate | C2: loss_carryback | D2: loss_carryforward | E2: machines_cost_recovery | F2: buildings_cost_recovery | G2: intangibles_cost_recovery | H2: inventory | I2: allowance_corporate_equity | J2: patent_box | K2: r_and_d_credit | L2: digital_services_tax | M2: corporate_alt_minimum | N2: corporate_surtax | O2: corporate_other_rev | P2: top_income_rate | Q2: threshold_top_income_rate | R2: tax_wedge | S2: personal_surtax | T2: personal_other_rev | U2: capital_gains_rate | V2: dividends_rate | W2: vat_rate | X2: vat_threshold | Y2: vat_base | Z2: property_tax | AA2: property_tax_collections | AB2: net_wealth | AC2: estate_or_inheritance_tax | AD2: transfer_tax | AE2: asset_tax | AF2: capital_duties | AG2: financial_transaction_tax | AH2: dividends_exemption | AI2: capital_gains_exemption | AJ2: country_limitations | AK2: dividends_withholding_tax | AL2: interest_withholding_tax | AM2: royalties_withholding_tax | AN2: tax_treaties | AO2: cfc_rules | AP2: thin_capitalization_rules | AQ2: minimum_tax
A3: Austria | B3: 0.23 | C3: 0 | D3: 75 | E3: 0.88436503 | F3: 0.33847473 | G3: 0.7378887 | H3: 1 | I3: 0 | J3: 0 | K3: 0.17 | L3: 1 | M3: 3 | N3: 0 | O3: 0.278569 | P3: 0.55 | Q3: 17.80329 | R3: 1.1311761 | S3: 0 | T3: 0 | U3: 0.275 | V3: 0.275 | W3: 20 | X3: 75017.424 | Y3: 0.61997648 | Z3: 0 | AA3: 0.11045113 | AB3: 0 | AC3: 0 | AD3: 1 | AE3: 1 | AF3: 0 | AG3: 0 | AH3: 1 | AI3: 1 | AJ3: 0 | AK3: 0.275 | AL3: 0 | AM3: 0.2 | AN3: 89 | AO3: 0.66666667 | AP3: 1 | AQ3: 1
A4: Australia | B4: 0.3 | C4: 0 | D4: 100 | E4: 0.85148497 | F4: 0.47931867 | G4: 0.54795391 | H4: 0.5 | I4: 0 | J4: 0 | K4: 0.1525 | L4: 0 | M4: 3 | N4: 0 | O4: 0 | P4: 0.47 | Q4: 1.73421 | R4: 1.3329211 | S4: 0 | T4: 0 | U4: 0.235 | V4: 0.24285714 | W4: 10 | X4: 54350.307 | Y4: 0.45951336 | Z4: 1 | AA4: 0.036917013 | AB4: 0 | AC4: 0 | AD4: 1 | AE4: 1 | AF4: 0 | AG4: 0 | AH4: 1 | AI4: 1 | AJ4: 0 | AK4: 0.3 | AL4: 0.1 | AM4: 0.3 | AN4: 48 | AO4: 0.33333333 | AP4: 1 | AQ4: 1
A5: Belgium | B5: 0.25 | C5: 0 | D5: 70 | E5: 0.86986525 | F5: 0.54795391 | G5: 0.86986525 | H5: 1 | I5: 0 | J5: 1 | K5: 0.155 | L5: 0 | M5: 2 | N5: 0 | O5: 0.018283 | P5: 0.60172143 | Q5: 1.022341 | R5: 1.2813917 | S5: 0 | T5: 0 | U5: 0 | V5: 0.3 | W5: 21 | X5: 34879.957 | Y5: 0.43331369 | Z5: 0.5 | AA5: 0.76110655 | AB5: 0.5 | AC5: 1 | AD5: 1 | AE5: 1 | AF5: 0 | AG5: 1 | AH5: 1 | AI5: 1 | AJ5: 0 | AK5: 0.3 | AL5: 0.3 | AM5: 0.3 | AN5: 95 | AO5: 0.66666667 | AP5: 1 | AQ5: 1
A6: Canada | B6: 0.25981152 | C6: 3 | D6: 20 | E6: 0.9673913 | F6: 0.625 | G6: 0.51896552 | H6: 0.5 | I6: 0 | J6: 0 | K6: 0.2125 | L6: 0 | M6: 2 | N6: 0 | O6: 0.444411 | P6: 0.535296 | Q6: 2.802078 | R6: 1.2197173 | S6: 0 | T6: 0 | U6: 0.2675 | V6: 0.39343524 | W6: 12.3 | X6: 26420.405 | Y6: 0.52674595 | Z6: 0.5 | AA6: 1.2084102 | AB6: 0 | AC6: 0 | AD6: 1 | AE6: 1 | AF6: 1 | AG6: 0 | AH6: 1 | AI6: 0.5 | AJ6: 1 | AK6: 0.25 | AL6: 0.25 | AM6: 0.25 | AN6: 96 | AO6: 0.33333333 | AP6: 0.5 | AQ6: 1
A7: Switzerland | B7: 0.19607821 | C7: 0 | D7: 7 | E7: 0.86 | F7: 0.55483871 | G7: 0.90526316 | H7: 1 | I7: 0 | J7: 1 | K7: -0.01 | L7: 1 | M7: 1 | N7: 0 | O7: 1.077651 | P7: 0.4141 | Q7: 3.122135 | R7: 1.3383172 | S7: 0 | T7: 0 | U7: 0 | V7: 0.22155 | W7: 8.1 | X7: 102786.65 | Y7: 0.68135293 | Z7: 0.5 | AA7: 0.095367028 | AB7: 1 | AC7: 1 | AD7: 1 | AE7: 1 | AF7: 1 | AG7: 1 | AH7: 1 | AI7: 1 | AJ7: 0 | AK7: 0.35 | AL7: 0.35 | AM7: 0 | AN7: 110 | AO7: 0 | AP7: 0.5 | AQ7: 0.5
A8: Chile | B8: 0.27 | C8: 0 | D8: 100 | E8: 0.63261166 | F8: 0.33847473 | G8: 0 | H8: 0.5 | I8: 0 | J8: 0 | K8: 0.275 | L8: 0 | M8: 0 | N8: 0 | O8: 0.107049 | P8: 0.40000001 | Q8: 17.951571 | R8: 1.214444 | S8: 0 | T8: 0 | U8: 0.4 | V8: 0.2390411 | W8: 19 | X8: 0 | Y8: 0.67226555 | Z8: 0.5 | AA8: 0.00088103 | AB8: 0 | AC8: 1 | AD8: 0 | AE8: 1 | AF8: 0 | AG8: 0 | AH8: 0 | AI8: 0 | AJ8: 1 | AK8: 0.35 | AL8: 0.35 | AM8: 0.3 | AN8: 37 | AO8: 0.5 | AP8: 0.5 | AQ8: 0
A9: Colombia | B9: 0.35 | C9: 0 | D9: 12 | E9: 0.7378887 | F9: 0.30595653 | G9: 0.86986525 | H9: 0.5 | I9: 0 | J9: 0 | K9: 0.0725 | L9: 1 | M9: 3 | N9: 0 | O9: 0.086333 | P9: 0.38999999 | Q9: 50.77305 | R9: 0 | S9: 0 | T9: 1.613716 | U9: 0.15 | V9: 0.2 | W9: 19 | X9: 0 | Y9: 0.38530428 | Z9: 0.5 | AA9: 0.000142808 | AB9: 1 | AC9: 1 | AD9: 1 | AE9: 0 | AF9: 1 | AG9: 1 | AH9: 0 | AI9: 0 | AJ9: 0 | AK9: 0.2 | AL9: 0.2 | AM9: 0.2 | AN9: 14 | AO9: 0.66666667 | AP9: 0.5 | AQ9: 0
A10: Costa Rica | B10: 0.3 | C10: 0 | D10: 3 | E10: 0.82245669 | F10: 0.27895845 | G10: 0.7378887 | H10: 0.5 | I10: 0 | J10: 0 | K10: -0.02 | L10: 0 | M10: 5 | N10: 0 | O10: 1.212838 | P10: 0.33615205 | Q10: 6.865182 | R10: 1.0643568 | S10: 0 | T10: 7.993262 | U10: 0.15 | V10: 0.15 | W10: 13 | X10: 0 | Y10: 0.50135879 | Z10: 0.5 | AA10: 0.000505989 | AB10: 0 | AC10: 0 | AD10: 1 | AE10: 1 | AF10: 0 | AG10: 1 | AH10: 1 | AI10: 1 | AJ10: 0 | AK10: 0.15 | AL10: 0.15 | AM10: 0.25 | AN10: 4 | AO10: 0 | AP10: 1 | AQ10: 0
A11: Czech Republic | B11: 0.21 | C11: 2 | D11: 5 | E11: 0.87387911 | F11: 0.54322283 | G11: 0.84131885 | H11: 0.5 | I11: 0 | J11: 0 | K11: 0.205 | L11: 0 | M11: 1 | N11: 0 | O11: 0 | P11: 0.346 | Q11: 2.879198 | R11: 1.1058366 | S11: 0 | T11: 0 | U11: 0.23 | V11: 0.23 | W11: 21 | X11: 154336.46 | Y11: 0.5994904 | Z11: 0.5 | AA11: 0.004302784 | AB11: 0 | AC11: 1 | AD11: 0 | AE11: 0 | AF11: 0 | AG11: 0 | AH11: 1 | AI11: 1 | AJ11: 1 | AK11: 0.15 | AL11: 0.15 | AM11: 0.15 | AN11: 98 | AO11: 0.33333333 | AP11: 1 | AQ11: 1
A12: Germany | B12: 0.30058462 | C12: 2 | D12: 70 | E12: 0.87651404 | F12: 0.39140601 | G12: 0.86986525 | H12: 1 | I12: 0 | J12: 0 | K12: 0.2625 | L12: 0 | M12: 1 | N12: 1 | O12: 0 | P12: 0.47475 | Q12: 4.654217 | R12: 1.0615432 | S12: 1 | T12: 0 | U12: 0.26375 | V12: 0.26375 | W12: 19 | X12: 35060.901 | Y12: 0.53475626 | Z12: 0.5 | AA12: 0.23305556 | AB12: 0 | AC12: 1 | AD12: 1 | AE12: 0 | AF12: 0 | AG12: 0 | AH12: 0.95 | AI12: 0.95 | AJ12: 0 | AK12: 0.26375 | AL12: 0 | AM12: 0.15825 | AN12: 95 | AO12: 0.33333333 | AP12: 1 | AQ12: 1
A13: Denmark | B13: 0.22 | C13: 0 | D13: 60 | E13: 0.82692308 | F13: 0.39140601 | G13: 0.81340644 | H13: 0 | I13: 0 | J13: 0 | K13: 0.01 | L13: 1 | M13: 1 | N13: 0 | O13: 0.517328 | P13: 0.559044 | Q13: 1.257352 | R13: 1.2214928 | S13: 0 | T13: 0 | U13: 0.42 | V13: 0.42 | W13: 25 | X13: 8025.5753 | Y13: 0.62634992 | Z13: 0.5 | AA13: 0.10983206 | AB13: 0 | AC13: 1 | AD13: 1 | AE13: 0 | AF13: 0 | AG13: 0 | AH13: 1 | AI13: 1 | AJ13: 1 | AK13: 0.27 | AL13: 0.22 | AM13: 0.22 | AN13: 77 | AO13: 0.66666667 | AP13: 1 | AQ13: 1
A14: Estonia | B14: 0.22 | C14: 100 | D14: 100 | E14: 1 | F14: 1 | G14: 1 | H14: 1 | I14: 1 | J14: 0 | K14: 0.04 | L14: 0 | M14: 1 | N14: 0 | O14: 0 | P14: 0.2 | Q14: 0.333272 | R14: 1.2442788 | S14: 0 | T14: 0 | U14: 0.22 | V14: 0 | W14: 24 | X14: 68524.597 | Y14: 0.69983246 | Z14: 1 | AA14: 0.11156757 | AB14: 0 | AC14: 0 | AD14: 0 | AE14: 0 | AF14: 0 | AG14: 0 | AH14: 1 | AI14: 1 | AJ14: 1 | AK14: 0 | AL14: 0 | AM14: 0.1 | AN14: 63 | AO14: 0.33333333 | AP14: 1 | AQ14: 0
... A40: United States | B40: 0.25569714 | C40: 0 | D40: 80 | E40: 1 | F40: 1 | G40: 0.63275134 | H40: 1 | I40: 0 | J40: 1 | K40: 0.0275 | L40: 0 | M40: 2 | N40: 0 | O40: 0 | P40: 0.46 | Q40: 8.834464 | R40: 1.2495081 | S40: 0 | T40: 0 | U40: 0.2887 | V40: 0.28666715 | W40: 7.5 | X40: 0 | Y40: 0.35887465 | Z40: 0.5 | AA40: 1.8121467 | AB40: 0 | AC40: 1 | AD40: 1 | AE40: 1 | AF40: 0 | AG40: 0 | AH40: 1 | AI40: 0 | AJ40: 0 | AK40: 0.3 | AL40: 0.3 | AM40: 0.3 | AN40: 64 | AO40: 0.33333333 | AP40: 1 | AQ40: 1

Sheet AbsValues
A1: ABS() of corporate_other_rev / personal_other_rev (LIVE)
A2: country | B2: corporate_other_rev | C2: personal_other_rev
A3: =RawData!A3 -> Austria | B3: =ABS(RawData!O3) -> 0.278569 | C3: =ABS(RawData!T3) -> 0
A4: =RawData!A4 -> Australia | B4: =ABS(RawData!O4) -> 0 | C4: =ABS(RawData!T4) -> 0
A5: =RawData!A5 -> Belgium | B5: =ABS(RawData!O5) -> 0.018283 | C5: =ABS(RawData!T5) -> 0
A6: =RawData!A6 -> Canada | B6: =ABS(RawData!O6) -> 0.444411 | C6: =ABS(RawData!T6) -> 0
A7: =RawData!A7 -> Switzerland | B7: =ABS(RawData!O7) -> 1.077651 | C7: =ABS(RawData!T7) -> 0
A8: =RawData!A8 -> Chile | B8: =ABS(RawData!O8) -> 0.107049 | C8: =ABS(RawData!T8) -> 0
A9: =RawData!A9 -> Colombia | B9: =ABS(RawData!O9) -> 0.086333 | C9: =ABS(RawData!T9) -> 1.613716
A10: =RawData!A10 -> Costa Rica | B10: =ABS(RawData!O10) -> 1.212838 | C10: =ABS(RawData!T10) -> 7.993262
A11: =RawData!A11 -> Czech Republic | B11: =ABS(RawData!O11) -> 0 | C11: =ABS(RawData!T11) -> 0
A12: =RawData!A12 -> Germany | B12: =ABS(RawData!O12) -> 0 | C12: =ABS(RawData!T12) -> 0
A13: =RawData!A13 -> Denmark | B13: =ABS(RawData!O13) -> 0.517328 | C13: =ABS(RawData!T13) -> 0
A14: =RawData!A14 -> Estonia | B14: =ABS(RawData!O14) -> 0 | C14: =ABS(RawData!T14) -> 0
... A40: =RawData!A40 -> United States | B40: =ABS(RawData!O40) -> 0 | C40: =ABS(RawData!T40) -> 0

Sheet ZScores
A1: Z-Scores (LIVE)
A2: z = (x - AVERAGE) / STDEV, across the country cross-section. corporate_other_rev/personal_other_rev use ABS(x) first (can be recorded as a negative revenue-impact figure). 30 variables then sign-flipped (*-1) so a higher z-score always means more competitive.
A3: country | B3: corporate_rate | C3: loss_carryback | D3: loss_carryforward | E3: machines_cost_recovery | F3: buildings_cost_recovery | G3: intangibles_cost_recovery | H3: inventory | I3: allowance_corporate_equity | J3: patent_box | K3: r_and_d_credit | L3: digital_services_tax | M3: corporate_alt_minimum | N3: corporate_surtax | O3: corporate_other_rev | P3: top_income_rate | Q3: threshold_top_income_rate | R3: tax_wedge | S3: personal_surtax | T3: personal_other_rev | U3: capital_gains_rate | V3: dividends_rate | W3: vat_rate | X3: vat_threshold | Y3: vat_base | Z3: property_tax | AA3: property_tax_collections | AB3: net_wealth | AC3: estate_or_inheritance_tax | AD3: transfer_tax | AE3: asset_tax | AF3: capital_duties | AG3: financial_transaction_tax | AH3: dividends_exemption | AI3: capital_gains_exemption | AJ3: country_limitations | AK3: dividends_withholding_tax | AL3: interest_withholding_tax | AM3: royalties_withholding_tax | AN3: tax_treaties | AO3: cfc_rules | AP3: thin_capitalization_rules | AQ3: minimum_tax
A4: =RawData!A3 -> Austria | B4: =-1*((RawData!B3-AVERAGE(RawData!$B$3:$B$40))/STDEV(RawData!$B$3:$B$40)) -> 0.21976872 | C4: =((RawData!C3-AVERAGE(RawData!$C$3:$C$40))/STDEV(RawData!$C$3:$C$40)) -> -0.24662998 | D4: =((RawData!D3-AVERAGE(RawData!$D$3:$D$40))/STDEV(RawData!$D$3:$D$40)) -> 0.71668063 | E4: =((RawData!E3-AVERAGE(RawData!$E$3:$E$40))/STDEV(RawData!$E$3:$E$40)) -> 0.33941188 | F4: =((RawData!F3-AVERAGE(RawData!$F$3:$F$40))/STDEV(RawData!$F$3:$F$40)) -> -0.82888336 | G4: =((RawData!G3-AVERAGE(RawData!$G$3:$G$40))/STDEV(RawData!$G$3:$G$40)) -> -0.16428036 | H4: =((RawData!H3-AVERAGE(RawData!$H$3:$H$40))/STDEV(RawData!$H$3:$H$40)) -> 1.1791342 | I4: =((RawData!I3-AVERAGE(RawData!$I$3:$I$40))/STDEV(RawData!$I$3:$I$40)) -> -0.38409362 | J4: =-1*((RawData!J3-AVERAGE(RawData!$J$3:$J$40))/STDEV(RawData!$J$3:$J$40)) -> 0.9361174 | K4: =-1*((RawData!K3-AVERAGE(RawData!$K$3:$K$40))/STDEV(RawData!$K$3:$K$40)) -> -0.088694085 | L4: =-1*((RawData!L3-AVERAGE(RawData!$L$3:$L$40))/STDEV(RawData!$L$3:$L$40)) -> -1.4524631 | M4: =-1*((RawData!M3-AVERAGE(RawData!$M$3:$M$40))/STDEV(RawData!$M$3:$M$40)) -> -0.80926387 | N4: =-1*((RawData!N3-AVERAGE(RawData!$N$3:$N$40))/STDEV(RawData!$N$3:$N$40)) -> 0.33845396 | O4: =-1*((AbsValues!B3-AVERAGE(AbsValues!$B$3:$B$40))/STDEV(AbsValues!$B$3:$B$40)) -> 0.044741031 | P4: =-1*((RawData!P3-AVERAGE(RawData!$P$3:$P$40))/STDEV(RawData!$P$3:$P$40)) -> -0.95276284 | Q4: =-1*((RawData!Q3-AVERAGE(RawData!$Q$3:$Q$40))/STDEV(RawData!$Q$3:$Q$40)) -> -1.1429712 | R4: =-1*((RawData!R3-AVERAGE(RawData!$R$3:$R$40))/STDEV(RawData!$R$3:$R$40)) -> 0.40224409 | S4: =-1*((RawData!S3-AVERAGE(RawData!$S$3:$S$40))/STDEV(RawData!$S$3:$S$40)) -> 0.33845396 | T4: =-1*((AbsValues!C3-AVERAGE(AbsValues!$C$3:$C$40))/STDEV(AbsValues!$C$3:$C$40)) -> 0.32073762 | U4: =-1*((RawData!U3-AVERAGE(RawData!$U$3:$U$40))/STDEV(RawData!$U$3:$U$40)) -> -0.56879446 | V4: =-1*((RawData!V3-AVERAGE(RawData!$V$3:$V$40))/STDEV(RawData!$V$3:$V$40)) -> -0.24291245 | W4: =-1*((RawData!W3-AVERAGE(RawData!$W$3:$W$40))/STDEV(RawData!$W$3:$W$40)) -> -0.12455652 | X4: =-1*((RawData!X3-AVERAGE(RawData!$X$3:$X$40))/STDEV(RawData!$X$3:$X$40)) -> -0.39047243 | Y4: =((RawData!Y3-AVERAGE(RawData!$Y$3:$Y$40))/STDEV(RawData!$Y$3:$Y$40)) -> 0.52626463 | Z4: =((RawData!Z3-AVERAGE(RawData!$Z$3:$Z$40))/STDEV(RawData!$Z$3:$Z$40)) -> -2.1543217 | AA4: =-1*((RawData!AA3-AVERAGE(RawData!$AA$3:$AA$40))/STDEV(RawData!$AA$3:$AA$40)) -> 0.52679341 | AB4: =-1*((RawData!AB3-AVERAGE(RawData!$AB$3:$AB$40))/STDEV(RawData!$AB$3:$AB$40)) -> 0.44275606 | AC4: =-1*((RawData!AC3-AVERAGE(RawData!$AC$3:$AC$40))/STDEV(RawData!$AC$3:$AC$40)) -> 1.4524631 | AD4: =-1*((RawData!AD3-AVERAGE(RawData!$AD$3:$AD$40))/STDEV(RawData!$AD$3:$AD$40)) -> -0.42727718 | AE4: =-1*((RawData!AE3-AVERAGE(RawData!$AE$3:$AE$40))/STDEV(RawData!$AE$3:$AE$40)) -> -0.9361174 | AF4: =-1*((RawData!AF3-AVERAGE(RawData!$AF$3:$AF$40))/STDEV(RawData!$AF$3:$AF$40)) -> 0.58969853 | AG4: =-1*((RawData!AG3-AVERAGE(RawData!$AG$3:$AG$40))/STDEV(RawData!$AG$3:$AG$40)) -> 0.79687605 | AH4: =((RawData!AH3-AVERAGE(RawData!$AH$3:$AH$40))/STDEV(RawData!$AH$3:$AH$40)) -> 0.32819245 | AI4: =((RawData!AI3-AVERAGE(RawData!$AI$3:$AI$40))/STDEV(RawData!$AI$3:$AI$40)) -> 0.55436816 | AJ4: =-1*((RawData!AJ3-AVERAGE(RawData!$AJ$3:$AJ$40))/STDEV(RawData!$AJ$3:$AJ$40)) -> 0.98675438 | AK4: =-1*((RawData!AK3-AVERAGE(RawData!$AK$3:$AK$40))/STDEV(RawData!$AK$3:$AK$40)) -> -0.70469318 | AL4: =-1*((RawData!AL3-AVERAGE(RawData!$AL$3:$AL$40))/STDEV(RawData!$AL$3:$AL$40)) -> 1.2947279 | AM4: =-1*((RawData!AM3-AVERAGE(RawData!$AM$3:$AM$40))/STDEV(RawData!$AM$3:$AM$40)) -> -0.24215868 | AN4: =((RawData!AN3-AVERAGE(RawData!$AN$3:$AN$40))/STDEV(RawData!$AN$3:$AN$40)) -> 0.49219182 | AO4: =-1*((RawData!AO3-AVERAGE(RawData!$AO$3:$AO$40))/STDEV(RawData!$AO$3:$AO$40)) -> -1.3355779 | AP4: =-1*((RawData!AP3-AVERAGE(RawData!$AP$3:$AP$40))/STDEV(RawData!$AP$3:$AP$40)) -> -0.48376743 | AQ4: =-1*((RawData!AQ3-AVERAGE(RawData!$AQ$3:$AQ$40))/STDEV(RawData!$AQ$3:$AQ$40)) -> -0.68274065
A5: =RawData!A4 -> Australia | B5: =-1*((RawData!B4-AVERAGE(RawData!$B$3:$B$40))/STDEV(RawData!$B$3:$B$40)) -> -1.0631397 | C5: =((RawData!C4-AVERAGE(RawData!$C$3:$C$40))/STDEV(RawData!$C$3:$C$40)) -> -0.24662998 | D5: =((RawData!D4-AVERAGE(RawData!$D$3:$D$40))/STDEV(RawData!$D$3:$D$40)) -> 1.3509999 | E5: =((RawData!E4-AVERAGE(RawData!$E$3:$E$40))/STDEV(RawData!$E$3:$E$40)) -> -0.065238195 | F5: =((RawData!F4-AVERAGE(RawData!$F$3:$F$40))/STDEV(RawData!$F$3:$F$40)) -> -0.10047078 | G5: =((RawData!G4-AVERAGE(RawData!$G$3:$G$40))/STDEV(RawData!$G$3:$G$40)) -> -1.2377336 | H5: =((RawData!H4-AVERAGE(RawData!$H$3:$H$40))/STDEV(RawData!$H$3:$H$40)) -> -0.2662561 | I5: =((RawData!I4-AVERAGE(RawData!$I$3:$I$40))/STDEV(RawData!$I$3:$I$40)) -> -0.38409362 | J5: =-1*((RawData!J4-AVERAGE(RawData!$J$3:$J$40))/STDEV(RawData!$J$3:$J$40)) -> 0.9361174 | K5: =-1*((RawData!K4-AVERAGE(RawData!$K$3:$K$40))/STDEV(RawData!$K$3:$K$40)) -> 0.064504789 | L5: =-1*((RawData!L4-AVERAGE(RawData!$L$3:$L$40))/STDEV(RawData!$L$3:$L$40)) -> 0.6703676 | M5: =-1*((RawData!M4-AVERAGE(RawData!$M$3:$M$40))/STDEV(RawData!$M$3:$M$40)) -> -0.80926387 | N5: =-1*((RawData!N4-AVERAGE(RawData!$N$3:$N$40))/STDEV(RawData!$N$3:$N$40)) -> 0.33845396 | O5: =-1*((AbsValues!B4-AVERAGE(AbsValues!$B$3:$B$40))/STDEV(AbsValues!$B$3:$B$40)) -> 0.59391264 | P5: =-1*((RawData!P4-AVERAGE(RawData!$P$3:$P$40))/STDEV(RawData!$P$3:$P$40)) -> -0.09193706 | Q5: =-1*((RawData!Q4-AVERAGE(RawData!$Q$3:$Q$40))/STDEV(RawData!$Q$3:$Q$40)) -> 0.57078064 | R5: =-1*((RawData!R4-AVERAGE(RawData!$R$3:$R$40))/STDEV(RawData!$R$3:$R$40)) -> -0.38675428 | S5: =-1*((RawData!S4-AVERAGE(RawData!$S$3:$S$40))/STDEV(RawData!$S$3:$S$40)) -> 0.33845396 | T5: =-1*((AbsValues!C4-AVERAGE(AbsValues!$C$3:$C$40))/STDEV(AbsValues!$C$3:$C$40)) -> 0.32073762 | U5: =-1*((RawData!U4-AVERAGE(RawData!$U$3:$U$40))/STDEV(RawData!$U$3:$U$40)) -> -0.26627597 | V5: =-1*((RawData!V4-AVERAGE(RawData!$V$3:$V$40))/STDEV(RawData!$V$3:$V$40)) -> 0.038335188 | W5: =-1*((RawData!W4-AVERAGE(RawData!$W$3:$W$40))/STDEV(RawData!$W$3:$W$40)) -> 1.7994873 | X5: =-1*((RawData!X4-AVERAGE(RawData!$X$3:$X$40))/STDEV(RawData!$X$3:$X$40)) -> 0.034288031 | Y5: =((RawData!Y4-AVERAGE(RawData!$Y$3:$Y$40))/STDEV(RawData!$Y$3:$Y$40)) -> -0.769383 | Z5: =((RawData!Z4-AVERAGE(RawData!$Z$3:$Z$40))/STDEV(RawData!$Z$3:$Z$40)) -> 2.5236339 | AA5: =-1*((RawData!AA4-AVERAGE(RawData!$AA$3:$AA$40))/STDEV(RawData!$AA$3:$AA$40)) -> 0.65847877 | AB5: =-1*((RawData!AB4-AVERAGE(RawData!$AB$3:$AB$40))/STDEV(RawData!$AB$3:$AB$40)) -> 0.44275606 | AC5: =-1*((RawData!AC4-AVERAGE(RawData!$AC$3:$AC$40))/STDEV(RawData!$AC$3:$AC$40)) -> 1.4524631 | AD5: =-1*((RawData!AD4-AVERAGE(RawData!$AD$3:$AD$40))/STDEV(RawData!$AD$3:$AD$40)) -> -0.42727718 | AE5: =-1*((RawData!AE4-AVERAGE(RawData!$AE$3:$AE$40))/STDEV(RawData!$AE$3:$AE$40)) -> -0.9361174 | AF5: =-1*((RawData!AF4-AVERAGE(RawData!$AF$3:$AF$40))/STDEV(RawData!$AF$3:$AF$40)) -> 0.58969853 | AG5: =-1*((RawData!AG4-AVERAGE(RawData!$AG$3:$AG$40))/STDEV(RawData!$AG$3:$AG$40)) -> 0.79687605 | AH5: =((RawData!AH4-AVERAGE(RawData!$AH$3:$AH$40))/STDEV(RawData!$AH$3:$AH$40)) -> 0.32819245 | AI5: =((RawData!AI4-AVERAGE(RawData!$AI$3:$AI$40))/STDEV(RawData!$AI$3:$AI$40)) -> 0.55436816 | AJ5: =-1*((RawData!AJ4-AVERAGE(RawData!$AJ$3:$AJ$40))/STDEV(RawData!$AJ$3:$AJ$40)) -> 0.98675438 | AK5: =-1*((RawData!AK4-AVERAGE(RawData!$AK$3:$AK$40))/STDEV(RawData!$AK$3:$AK$40)) -> -0.95570405 | AL5: =-1*((RawData!AL4-AVERAGE(RawData!$AL$3:$AL$40))/STDEV(RawData!$AL$3:$AL$40)) -> 0.42149551 | AM5: =-1*((RawData!AM4-AVERAGE(RawData!$AM$3:$AM$40))/STDEV(RawData!$AM$3:$AM$40)) -> -1.250545 | AN5: =((RawData!AN4-AVERAGE(RawData!$AN$3:$AN$40))/STDEV(RawData!$AN$3:$AN$40)) -> -1.0476372 | AO5: =-1*((RawData!AO4-AVERAGE(RawData!$AO$3:$AO$40))/STDEV(RawData!$AO$3:$AO$40)) -> 0.61642058 | AP5: =-1*((RawData!AP4-AVERAGE(RawData!$AP$3:$AP$40))/STDEV(RawData!$AP$3:$AP$40)) -> -0.48376743 | AQ5: =-1*((RawData!AQ4-AVERAGE(RawData!$AQ$3:$AQ$40))/STDEV(RawData!$AQ$3:$AQ$40)) -> -0.68274065
A6: =RawData!A5 -> Belgium | B6: =-1*((RawData!B5-AVERAGE(RawData!$B$3:$B$40))/STDEV(RawData!$B$3:$B$40)) -> -0.14677654 | C6: =((RawData!C5-AVERAGE(RawData!$C$3:$C$40))/STDEV(RawData!$C$3:$C$40)) -> -0.24662998 | D6: =((RawData!D5-AVERAGE(RawData!$D$3:$D$40))/STDEV(RawData!$D$3:$D$40)) -> 0.58981677 | E6: =((RawData!E5-AVERAGE(RawData!$E$3:$E$40))/STDEV(RawData!$E$3:$E$40)) -> 0.16096528 | F6: =((RawData!F5-AVERAGE(RawData!$F$3:$F$40))/STDEV(RawData!$F$3:$F$40)) -> 0.25449495 | G6: =((RawData!G5-AVERAGE(RawData!$G$3:$G$40))/STDEV(RawData!$G$3:$G$40)) -> 0.58161067 | H6: =((RawData!H5-AVERAGE(RawData!$H$3:$H$40))/STDEV(RawData!$H$3:$H$40)) -> 1.1791342 | I6: =((RawData!I5-AVERAGE(RawData!$I$3:$I$40))/STDEV(RawData!$I$3:$I$40)) -> -0.38409362 | J6: =-1*((RawData!J5-AVERAGE(RawData!$J$3:$J$40))/STDEV(RawData!$J$3:$J$40)) -> -1.0401304 | K6: =-1*((RawData!K5-AVERAGE(RawData!$K$3:$K$40))/STDEV(RawData!$K$3:$K$40)) -> 0.042619236 | L6: =-1*((RawData!L5-AVERAGE(RawData!$L$3:$L$40))/STDEV(RawData!$L$3:$L$40)) -> 0.6703676 | M6: =-1*((RawData!M5-AVERAGE(RawData!$M$3:$M$40))/STDEV(RawData!$M$3:$M$40)) -> -0.09410045 | N6: =-1*((RawData!N5-AVERAGE(RawData!$N$3:$N$40))/STDEV(RawData!$N$3:$N$40)) -> 0.33845396 | O6: =-1*((AbsValues!B5-AVERAGE(AbsValues!$B$3:$B$40))/STDEV(AbsValues!$B$3:$B$40)) -> 0.55786949 | P6: =-1*((RawData!P5-AVERAGE(RawData!$P$3:$P$40))/STDEV(RawData!$P$3:$P$40)) -> -1.5093021 | Q6: =-1*((RawData!Q5-AVERAGE(RawData!$Q$3:$Q$40))/STDEV(RawData!$Q$3:$Q$40)) -> 0.64670078 | R6: =-1*((RawData!R5-AVERAGE(RawData!$R$3:$R$40))/STDEV(RawData!$R$3:$R$40)) -> -0.1852295 | S6: =-1*((RawData!S5-AVERAGE(RawData!$S$3:$S$40))/STDEV(RawData!$S$3:$S$40)) -> 0.33845396 | T6: =-1*((AbsValues!C5-AVERAGE(AbsValues!$C$3:$C$40))/STDEV(AbsValues!$C$3:$C$40)) -> 0.32073762 | U6: =-1*((RawData!U5-AVERAGE(RawData!$U$3:$U$40))/STDEV(RawData!$U$3:$U$40)) -> 1.5110201 | V6: =-1*((RawData!V5-AVERAGE(RawData!$V$3:$V$40))/STDEV(RawData!$V$3:$V$40)) -> -0.46166058 | W6: =-1*((RawData!W5-AVERAGE(RawData!$W$3:$W$40))/STDEV(RawData!$W$3:$W$40)) -> -0.3169609 | X6: =-1*((RawData!X5-AVERAGE(RawData!$X$3:$X$40))/STDEV(RawData!$X$3:$X$40)) -> 0.43445197 | Y6: =((RawData!Y5-AVERAGE(RawData!$Y$3:$Y$40))/STDEV(RawData!$Y$3:$Y$40)) -> -0.98093024 | Z6: =((RawData!Z5-AVERAGE(RawData!$Z$3:$Z$40))/STDEV(RawData!$Z$3:$Z$40)) -> 0.18465614 | AA6: =-1*((RawData!AA5-AVERAGE(RawData!$AA$3:$AA$40))/STDEV(RawData!$AA$3:$AA$40)) -> -0.63840445 | AB6: =-1*((RawData!AB5-AVERAGE(RawData!$AB$3:$AB$40))/STDEV(RawData!$AB$3:$AB$40)) -> -1.0867649 | AC6: =-1*((RawData!AC5-AVERAGE(RawData!$AC$3:$AC$40))/STDEV(RawData!$AC$3:$AC$40)) -> -0.6703676 | AD6: =-1*((RawData!AD5-AVERAGE(RawData!$AD$3:$AD$40))/STDEV(RawData!$AD$3:$AD$40)) -> -0.42727718 | AE6: =-1*((RawData!AE5-AVERAGE(RawData!$AE$3:$AE$40))/STDEV(RawData!$AE$3:$AE$40)) -> -0.9361174 | AF6: =-1*((RawData!AF5-AVERAGE(RawData!$AF$3:$AF$40))/STDEV(RawData!$AF$3:$AF$40)) -> 0.58969853 | AG6: =-1*((RawData!AG5-AVERAGE(RawData!$AG$3:$AG$40))/STDEV(RawData!$AG$3:$AG$40)) -> -1.2218766 | AH6: =((RawData!AH5-AVERAGE(RawData!$AH$3:$AH$40))/STDEV(RawData!$AH$3:$AH$40)) -> 0.32819245 | AI6: =((RawData!AI5-AVERAGE(RawData!$AI$3:$AI$40))/STDEV(RawData!$AI$3:$AI$40)) -> 0.55436816 | AJ6: =-1*((RawData!AJ5-AVERAGE(RawData!$AJ$3:$AJ$40))/STDEV(RawData!$AJ$3:$AJ$40)) -> 0.98675438 | AK6: =-1*((RawData!AK5-AVERAGE(RawData!$AK$3:$AK$40))/STDEV(RawData!$AK$3:$AK$40)) -> -0.95570405 | AL6: =-1*((RawData!AL5-AVERAGE(RawData!$AL$3:$AL$40))/STDEV(RawData!$AL$3:$AL$40)) -> -1.3249694 | AM6: =-1*((RawData!AM5-AVERAGE(RawData!$AM$3:$AM$40))/STDEV(RawData!$AM$3:$AM$40)) -> -1.250545 | AN6: =((RawData!AN5-AVERAGE(RawData!$AN$3:$AN$40))/STDEV(RawData!$AN$3:$AN$40)) -> 0.71753265 | AO6: =-1*((RawData!AO5-AVERAGE(RawData!$AO$3:$AO$40))/STDEV(RawData!$AO$3:$AO$40)) -> -1.3355779 | AP6: =-1*((RawData!AP5-AVERAGE(RawData!$AP$3:$AP$40))/STDEV(RawData!$AP$3:$AP$40)) -> -0.48376743 | AQ6: =-1*((RawData!AQ5-AVERAGE(RawData!$AQ$3:$AQ$40))/STDEV(RawData!$AQ$3:$AQ$40)) -> -0.68274065
A7: =RawData!A6 -> Canada | B7: =-1*((RawData!B6-AVERAGE(RawData!$B$3:$B$40))/STDEV(RawData!$B$3:$B$40)) -> -0.32659485 | C7: =((RawData!C6-AVERAGE(RawData!$C$3:$C$40))/STDEV(RawData!$C$3:$C$40)) -> -0.11369467 | D7: =((RawData!D6-AVERAGE(RawData!$D$3:$D$40))/STDEV(RawData!$D$3:$D$40)) -> -0.67882178 | E7: =((RawData!E6-AVERAGE(RawData!$E$3:$E$40))/STDEV(RawData!$E$3:$E$40)) -> 1.3612042 | F7: =((RawData!F6-AVERAGE(RawData!$F$3:$F$40))/STDEV(RawData!$F$3:$F$40)) -> 0.65295967 | G7: =((RawData!G6-AVERAGE(RawData!$G$3:$G$40))/STDEV(RawData!$G$3:$G$40)) -> -1.4015671 | H7: =((RawData!H6-AVERAGE(RawData!$H$3:$H$40))/STDEV(RawData!$H$3:$H$40)) -> -0.2662561 | I7: =((RawData!I6-AVERAGE(RawData!$I$3:$I$40))/STDEV(RawData!$I$3:$I$40)) -> -0.38409362 | J7: =-1*((RawData!J6-AVERAGE(RawData!$J$3:$J$40))/STDEV(RawData!$J$3:$J$40)) -> 0.9361174 | K7: =-1*((RawData!K6-AVERAGE(RawData!$K$3:$K$40))/STDEV(RawData!$K$3:$K$40)) -> -0.4607485 | L7: =-1*((RawData!L6-AVERAGE(RawData!$L$3:$L$40))/STDEV(RawData!$L$3:$L$40)) -> 0.6703676 | M7: =-1*((RawData!M6-AVERAGE(RawData!$M$3:$M$40))/STDEV(RawData!$M$3:$M$40)) -> -0.09410045 | N7: =-1*((RawData!N6-AVERAGE(RawData!$N$3:$N$40))/STDEV(RawData!$N$3:$N$40)) -> 0.33845396 | O7: =-1*((AbsValues!B6-AVERAGE(AbsValues!$B$3:$B$40))/STDEV(AbsValues!$B$3:$B$40)) -> -0.2822003 | P7: =-1*((RawData!P6-AVERAGE(RawData!$P$3:$P$40))/STDEV(RawData!$P$3:$P$40)) -> -0.79454306 | Q7: =-1*((RawData!Q6-AVERAGE(RawData!$Q$3:$Q$40))/STDEV(RawData!$Q$3:$Q$40)) -> 0.45689355 | R7: =-1*((RawData!R6-AVERAGE(RawData!$R$3:$R$40))/STDEV(RawData!$R$3:$R$40)) -> 0.055971157 | S7: =-1*((RawData!S6-AVERAGE(RawData!$S$3:$S$40))/STDEV(RawData!$S$3:$S$40)) -> 0.33845396 | T7: =-1*((AbsValues!C6-AVERAGE(AbsValues!$C$3:$C$40))/STDEV(AbsValues!$C$3:$C$40)) -> 0.32073762 | U7: =-1*((RawData!U6-AVERAGE(RawData!$U$3:$U$40))/STDEV(RawData!$U$3:$U$40)) -> -0.51207224 | V7: =-1*((RawData!V6-AVERAGE(RawData!$V$3:$V$40))/STDEV(RawData!$V$3:$V$40)) -> -1.279212 | W7: =-1*((RawData!W6-AVERAGE(RawData!$W$3:$W$40))/STDEV(RawData!$W$3:$W$40)) -> 1.3569572 | X7: =-1*((RawData!X6-AVERAGE(RawData!$X$3:$X$40))/STDEV(RawData!$X$3:$X$40)) -> 0.60831673 | Y7: =((RawData!Y6-AVERAGE(RawData!$Y$3:$Y$40))/STDEV(RawData!$Y$3:$Y$40)) -> -0.22651839 | Z7: =((RawData!Z6-AVERAGE(RawData!$Z$3:$Z$40))/STDEV(RawData!$Z$3:$Z$40)) -> 0.18465614 | AA7: =-1*((RawData!AA6-AVERAGE(RawData!$AA$3:$AA$40))/STDEV(RawData!$AA$3:$AA$40)) -> -1.4394387 | AB7: =-1*((RawData!AB6-AVERAGE(RawData!$AB$3:$AB$40))/STDEV(RawData!$AB$3:$AB$40)) -> 0.44275606 | AC7: =-1*((RawData!AC6-AVERAGE(RawData!$AC$3:$AC$40))/STDEV(RawData!$AC$3:$AC$40)) -> 1.4524631 | AD7: =-1*((RawData!AD6-AVERAGE(RawData!$AD$3:$AD$40))/STDEV(RawData!$AD$3:$AD$40)) -> -0.42727718 | AE7: =-1*((RawData!AE6-AVERAGE(RawData!$AE$3:$AE$40))/STDEV(RawData!$AE$3:$AE$40)) -> -0.9361174 | AF7: =-1*((RawData!AF6-AVERAGE(RawData!$AF$3:$AF$40))/STDEV(RawData!$AF$3:$AF$40)) -> -1.6511559 | AG7: =-1*((RawData!AG6-AVERAGE(RawData!$AG$3:$AG$40))/STDEV(RawData!$AG$3:$AG$40)) -> 0.79687605 | AH7: =((RawData!AH6-AVERAGE(RawData!$AH$3:$AH$40))/STDEV(RawData!$AH$3:$AH$40)) -> 0.32819245 | AI7: =((RawData!AI6-AVERAGE(RawData!$AI$3:$AI$40))/STDEV(RawData!$AI$3:$AI$40)) -> -0.71543233 | AJ7: =-1*((RawData!AJ6-AVERAGE(RawData!$AJ$3:$AJ$40))/STDEV(RawData!$AJ$3:$AJ$40)) -> -0.98675438 | AK7: =-1*((RawData!AK6-AVERAGE(RawData!$AK$3:$AK$40))/STDEV(RawData!$AK$3:$AK$40)) -> -0.45368232 | AL7: =-1*((RawData!AL6-AVERAGE(RawData!$AL$3:$AL$40))/STDEV(RawData!$AL$3:$AL$40)) -> -0.88835314 | AM7: =-1*((RawData!AM6-AVERAGE(RawData!$AM$3:$AM$40))/STDEV(RawData!$AM$3:$AM$40)) -> -0.74635186 | AN7: =((RawData!AN6-AVERAGE(RawData!$AN$3:$AN$40))/STDEV(RawData!$AN$3:$AN$40)) -> 0.75508946 | AO7: =-1*((RawData!AO6-AVERAGE(RawData!$AO$3:$AO$40))/STDEV(RawData!$AO$3:$AO$40)) -> 0.61642058 | AP7: =-1*((RawData!AP6-AVERAGE(RawData!$AP$3:$AP$40))/STDEV(RawData!$AP$3:$AP$40)) -> 1.5588062 | AQ7: =-1*((RawData!AQ6-AVERAGE(RawData!$AQ$3:$AQ$40))/STDEV(RawData!$AQ$3:$AQ$40)) -> -0.68274065
A8: =RawData!A7 -> Switzerland | B8: =-1*((RawData!B7-AVERAGE(RawData!$B$3:$B$40))/STDEV(RawData!$B$3:$B$40)) -> 0.84146229 | C8: =((RawData!C7-AVERAGE(RawData!$C$3:$C$40))/STDEV(RawData!$C$3:$C$40)) -> -0.24662998 | D8: =((RawData!D7-AVERAGE(RawData!$D$3:$D$40))/STDEV(RawData!$D$3:$D$40)) -> -1.0086678 | E8: =((RawData!E7-AVERAGE(RawData!$E$3:$E$40))/STDEV(RawData!$E$3:$E$40)) -> 0.03955503 | F8: =((RawData!F7-AVERAGE(RawData!$F$3:$F$40))/STDEV(RawData!$F$3:$F$40)) -> 0.29010155 | G8: =((RawData!G7-AVERAGE(RawData!$G$3:$G$40))/STDEV(RawData!$G$3:$G$40)) -> 0.78166878 | H8: =((RawData!H7-AVERAGE(RawData!$H$3:$H$40))/STDEV(RawData!$H$3:$H$40)) -> 1.1791342 | I8: =((RawData!I7-AVERAGE(RawData!$I$3:$I$40))/STDEV(RawData!$I$3:$I$40)) -> -0.38409362 | J8: =-1*((RawData!J7-AVERAGE(RawData!$J$3:$J$40))/STDEV(RawData!$J$3:$J$40)) -> -1.0401304 | K8: =-1*((RawData!K7-AVERAGE(RawData!$K$3:$K$40))/STDEV(RawData!$K$3:$K$40)) -> 1.4870658 | L8: =-1*((RawData!L7-AVERAGE(RawData!$L$3:$L$40))/STDEV(RawData!$L$3:$L$40)) -> -1.4524631 | M8: =-1*((RawData!M7-AVERAGE(RawData!$M$3:$M$40))/STDEV(RawData!$M$3:$M$40)) -> 0.62106297 | N8: =-1*((RawData!N7-AVERAGE(RawData!$N$3:$N$40))/STDEV(RawData!$N$3:$N$40)) -> 0.33845396 | O8: =-1*((AbsValues!B7-AVERAGE(AbsValues!$B$3:$B$40))/STDEV(AbsValues!$B$3:$B$40)) -> -1.5305712 | P8: =-1*((RawData!P7-AVERAGE(RawData!$P$3:$P$40))/STDEV(RawData!$P$3:$P$40)) -> 0.50956495 | Q8: =-1*((RawData!Q7-AVERAGE(RawData!$Q$3:$Q$40))/STDEV(RawData!$Q$3:$Q$40)) -> 0.42275978 | R8: =-1*((RawData!R7-AVERAGE(RawData!$R$3:$R$40))/STDEV(RawData!$R$3:$R$40)) -> -0.40785752 | S8: =-1*((RawData!S7-AVERAGE(RawData!$S$3:$S$40))/STDEV(RawData!$S$3:$S$40)) -> 0.33845396 | T8: =-1*((AbsValues!C7-AVERAGE(AbsValues!$C$3:$C$40))/STDEV(AbsValues!$C$3:$C$40)) -> 0.32073762 | U8: =-1*((RawData!U7-AVERAGE(RawData!$U$3:$U$40))/STDEV(RawData!$U$3:$U$40)) -> 1.5110201 | V8: =-1*((RawData!V7-AVERAGE(RawData!$V$3:$V$40))/STDEV(RawData!$V$3:$V$40)) -> 0.22477108 | W8: =-1*((RawData!W7-AVERAGE(RawData!$W$3:$W$40))/STDEV(RawData!$W$3:$W$40)) -> 2.1650556 | X8: =-1*((RawData!X7-AVERAGE(RawData!$X$3:$X$40))/STDEV(RawData!$X$3:$X$40)) -> -0.9611988 | Y8: =((RawData!Y7-AVERAGE(RawData!$Y$3:$Y$40))/STDEV(RawData!$Y$3:$Y$40)) -> 1.0218442 | Z8: =((RawData!Z7-AVERAGE(RawData!$Z$3:$Z$40))/STDEV(RawData!$Z$3:$Z$40)) -> 0.18465614 | AA8: =-1*((RawData!AA7-AVERAGE(RawData!$AA$3:$AA$40))/STDEV(RawData!$AA$3:$AA$40)) -> 0.55380611 | AB8: =-1*((RawData!AB7-AVERAGE(RawData!$AB$3:$AB$40))/STDEV(RawData!$AB$3:$AB$40)) -> -2.6162858 | AC8: =-1*((RawData!AC7-AVERAGE(RawData!$AC$3:$AC$40))/STDEV(RawData!$AC$3:$AC$40)) -> -0.6703676 | AD8: =-1*((RawData!AD7-AVERAGE(RawData!$AD$3:$AD$40))/STDEV(RawData!$AD$3:$AD$40)) -> -0.42727718 | AE8: =-1*((RawData!AE7-AVERAGE(RawData!$AE$3:$AE$40))/STDEV(RawData!$AE$3:$AE$40)) -> -0.9361174 | AF8: =-1*((RawData!AF7-AVERAGE(RawData!$AF$3:$AF$40))/STDEV(RawData!$AF$3:$AF$40)) -> -1.6511559 | AG8: =-1*((RawData!AG7-AVERAGE(RawData!$AG$3:$AG$40))/STDEV(RawData!$AG$3:$AG$40)) -> -1.2218766 | AH8: =((RawData!AH7-AVERAGE(RawData!$AH$3:$AH$40))/STDEV(RawData!$AH$3:$AH$40)) -> 0.32819245 | AI8: =((RawData!AI7-AVERAGE(RawData!$AI$3:$AI$40))/STDEV(RawData!$AI$3:$AI$40)) -> 0.55436816 | AJ8: =-1*((RawData!AJ7-AVERAGE(RawData!$AJ$3:$AJ$40))/STDEV(RawData!$AJ$3:$AJ$40)) -> 0.98675438 | AK8: =-1*((RawData!AK7-AVERAGE(RawData!$AK$3:$AK$40))/STDEV(RawData!$AK$3:$AK$40)) -> -1.4577258 | AL8: =-1*((RawData!AL7-AVERAGE(RawData!$AL$3:$AL$40))/STDEV(RawData!$AL$3:$AL$40)) -> -1.7615856 | AM8: =-1*((RawData!AM7-AVERAGE(RawData!$AM$3:$AM$40))/STDEV(RawData!$AM$3:$AM$40)) -> 1.774614 | AN8: =((RawData!AN7-AVERAGE(RawData!$AN$3:$AN$40))/STDEV(RawData!$AN$3:$AN$40)) -> 1.2808847 | AO8: =-1*((RawData!AO7-AVERAGE(RawData!$AO$3:$AO$40))/STDEV(RawData!$AO$3:$AO$40)) -> 2.5684191 | AP8: =-1*((RawData!AP7-AVERAGE(RawData!$AP$3:$AP$40))/STDEV(RawData!$AP$3:$AP$40)) -> 1.5588062 | AQ8: =-1*((RawData!AQ7-AVERAGE(RawData!$AQ$3:$AQ$40))/STDEV(RawData!$AQ$3:$AQ$40)) -> 0.44526564
A9: =RawData!A8 -> Chile | B9: =-1*((RawData!B8-AVERAGE(RawData!$B$3:$B$40))/STDEV(RawData!$B$3:$B$40)) -> -0.51332181 | C9: =((RawData!C8-AVERAGE(RawData!$C$3:$C$40))/STDEV(RawData!$C$3:$C$40)) -> -0.24662998 | D9: =((RawData!D8-AVERAGE(RawData!$D$3:$D$40))/STDEV(RawData!$D$3:$D$40)) -> 1.3509999 | E9: =((RawData!E8-AVERAGE(RawData!$E$3:$E$40))/STDEV(RawData!$E$3:$E$40)) -> -2.7588802 | F9: =((RawData!F8-AVERAGE(RawData!$F$3:$F$40))/STDEV(RawData!$F$3:$F$40)) -> -0.82888336 | G9: =((RawData!G8-AVERAGE(RawData!$G$3:$G$40))/STDEV(RawData!$G$3:$G$40)) -> -4.3346012 | H9: =((RawData!H8-AVERAGE(RawData!$H$3:$H$40))/STDEV(RawData!$H$3:$H$40)) -> -0.2662561 | I9: =((RawData!I8-AVERAGE(RawData!$I$3:$I$40))/STDEV(RawData!$I$3:$I$40)) -> -0.38409362 | J9: =-1*((RawData!J8-AVERAGE(RawData!$J$3:$J$40))/STDEV(RawData!$J$3:$J$40)) -> 0.9361174 | K9: =-1*((RawData!K8-AVERAGE(RawData!$K$3:$K$40))/STDEV(RawData!$K$3:$K$40)) -> -1.0078873 | L9: =-1*((RawData!L8-AVERAGE(RawData!$L$3:$L$40))/STDEV(RawData!$L$3:$L$40)) -> 0.6703676 | M9: =-1*((RawData!M8-AVERAGE(RawData!$M$3:$M$40))/STDEV(RawData!$M$3:$M$40)) -> 1.3362264 | N9: =-1*((RawData!N8-AVERAGE(RawData!$N$3:$N$40))/STDEV(RawData!$N$3:$N$40)) -> 0.33845396 | O9: =-1*((AbsValues!B8-AVERAGE(AbsValues!$B$3:$B$40))/STDEV(AbsValues!$B$3:$B$40)) -> 0.38287598 | P9: =-1*((RawData!P8-AVERAGE(RawData!$P$3:$P$40))/STDEV(RawData!$P$3:$P$40)) -> 0.66128539 | Q9: =-1*((RawData!Q8-AVERAGE(RawData!$Q$3:$Q$40))/STDEV(RawData!$Q$3:$Q$40)) -> -1.1587852 | R9: =-1*((RawData!R8-AVERAGE(RawData!$R$3:$R$40))/STDEV(RawData!$R$3:$R$40)) -> 0.076594324 | S9: =-1*((RawData!S8-AVERAGE(RawData!$S$3:$S$40))/STDEV(RawData!$S$3:$S$40)) -> 0.33845396 | T9: =-1*((AbsValues!C8-AVERAGE(AbsValues!$C$3:$C$40))/STDEV(AbsValues!$C$3:$C$40)) -> 0.32073762 | U9: =-1*((RawData!U8-AVERAGE(RawData!$U$3:$U$40))/STDEV(RawData!$U$3:$U$40)) -> -1.5141647 | V9: =-1*((RawData!V8-AVERAGE(RawData!$V$3:$V$40))/STDEV(RawData!$V$3:$V$40)) -> 0.071725254 | W9: =-1*((RawData!W8-AVERAGE(RawData!$W$3:$W$40))/STDEV(RawData!$W$3:$W$40)) -> 0.06784786 | X9: =-1*((RawData!X8-AVERAGE(RawData!$X$3:$X$40))/STDEV(RawData!$X$3:$X$40)) -> 1.1513215 | Y9: =((RawData!Y8-AVERAGE(RawData!$Y$3:$Y$40))/STDEV(RawData!$Y$3:$Y$40)) -> 0.94846881 | Z9: =((RawData!Z8-AVERAGE(RawData!$Z$3:$Z$40))/STDEV(RawData!$Z$3:$Z$40)) -> 0.18465614 | AA9: =-1*((RawData!AA8-AVERAGE(RawData!$AA$3:$AA$40))/STDEV(RawData!$AA$3:$AA$40)) -> 0.72301223 | AB9: =-1*((RawData!AB8-AVERAGE(RawData!$AB$3:$AB$40))/STDEV(RawData!$AB$3:$AB$40)) -> 0.44275606 | AC9: =-1*((RawData!AC8-AVERAGE(RawData!$AC$3:$AC$40))/STDEV(RawData!$AC$3:$AC$40)) -> -0.6703676 | AD9: =-1*((RawData!AD8-AVERAGE(RawData!$AD$3:$AD$40))/STDEV(RawData!$AD$3:$AD$40)) -> 2.2788116 | AE9: =-1*((RawData!AE8-AVERAGE(RawData!$AE$3:$AE$40))/STDEV(RawData!$AE$3:$AE$40)) -> -0.9361174 | AF9: =-1*((RawData!AF8-AVERAGE(RawData!$AF$3:$AF$40))/STDEV(RawData!$AF$3:$AF$40)) -> 0.58969853 | AG9: =-1*((RawData!AG8-AVERAGE(RawData!$AG$3:$AG$40))/STDEV(RawData!$AG$3:$AG$40)) -> 0.79687605 | AH9: =((RawData!AH8-AVERAGE(RawData!$AH$3:$AH$40))/STDEV(RawData!$AH$3:$AH$40)) -> -3.3615451 | AI9: =((RawData!AI8-AVERAGE(RawData!$AI$3:$AI$40))/STDEV(RawData!$AI$3:$AI$40)) -> -1.9852328 | AJ9: =-1*((RawData!AJ8-AVERAGE(RawData!$AJ$3:$AJ$40))/STDEV(RawData!$AJ$3:$AJ$40)) -> -0.98675438 | AK9: =-1*((RawData!AK8-AVERAGE(RawData!$AK$3:$AK$40))/STDEV(RawData!$AK$3:$AK$40)) -> -1.4577258 | AL9: =-1*((RawData!AL8-AVERAGE(RawData!$AL$3:$AL$40))/STDEV(RawData!$AL$3:$AL$40)) -> -1.7615856 | AM9: =-1*((RawData!AM8-AVERAGE(RawData!$AM$3:$AM$40))/STDEV(RawData!$AM$3:$AM$40)) -> -1.250545 | AN9: =((RawData!AN8-AVERAGE(RawData!$AN$3:$AN$40))/STDEV(RawData!$AN$3:$AN$40)) -> -1.4607621 | AO9: =-1*((RawData!AO8-AVERAGE(RawData!$AO$3:$AO$40))/STDEV(RawData!$AO$3:$AO$40)) -> -0.35957867 | AP9: =-1*((RawData!AP8-AVERAGE(RawData!$AP$3:$AP$40))/STDEV(RawData!$AP$3:$AP$40)) -> 1.5588062 | AQ9: =-1*((RawData!AQ8-AVERAGE(RawData!$AQ$3:$AQ$40))/STDEV(RawData!$AQ$3:$AQ$40)) -> 1.5732719
A10: =RawData!A9 -> Colombia | B10: =-1*((RawData!B9-AVERAGE(RawData!$B$3:$B$40))/STDEV(RawData!$B$3:$B$40)) -> -1.9795029 | C10: =((RawData!C9-AVERAGE(RawData!$C$3:$C$40))/STDEV(RawData!$C$3:$C$40)) -> -0.24662998 | D10: =((RawData!D9-AVERAGE(RawData!$D$3:$D$40))/STDEV(RawData!$D$3:$D$40)) -> -0.88180395 | E10: =((RawData!E9-AVERAGE(RawData!$E$3:$E$40))/STDEV(RawData!$E$3:$E$40)) -> -1.463251 | F10: =((RawData!F9-AVERAGE(RawData!$F$3:$F$40))/STDEV(RawData!$F$3:$F$40)) -> -0.99706005 | G10: =((RawData!G9-AVERAGE(RawData!$G$3:$G$40))/STDEV(RawData!$G$3:$G$40)) -> 0.58161067 | H10: =((RawData!H9-AVERAGE(RawData!$H$3:$H$40))/STDEV(RawData!$H$3:$H$40)) -> -0.2662561 | I10: =((RawData!I9-AVERAGE(RawData!$I$3:$I$40))/STDEV(RawData!$I$3:$I$40)) -> -0.38409362 | J10: =-1*((RawData!J9-AVERAGE(RawData!$J$3:$J$40))/STDEV(RawData!$J$3:$J$40)) -> 0.9361174 | K10: =-1*((RawData!K9-AVERAGE(RawData!$K$3:$K$40))/STDEV(RawData!$K$3:$K$40)) -> 0.7648425 | L10: =-1*((RawData!L9-AVERAGE(RawData!$L$3:$L$40))/STDEV(RawData!$L$3:$L$40)) -> -1.4524631 | M10: =-1*((RawData!M9-AVERAGE(RawData!$M$3:$M$40))/STDEV(RawData!$M$3:$M$40)) -> -0.80926387 | N10: =-1*((RawData!N9-AVERAGE(RawData!$N$3:$N$40))/STDEV(RawData!$N$3:$N$40)) -> 0.33845396 | O10: =-1*((AbsValues!B9-AVERAGE(AbsValues!$B$3:$B$40))/STDEV(AbsValues!$B$3:$B$40)) -> 0.42371556 | P10: =-1*((RawData!P9-AVERAGE(RawData!$P$3:$P$40))/STDEV(RawData!$P$3:$P$40)) -> 0.76888883 | Q10: =-1*((RawData!Q9-AVERAGE(RawData!$Q$3:$Q$40))/STDEV(RawData!$Q$3:$Q$40)) -> -4.6591642 | R10: =-1*((RawData!R9-AVERAGE(RawData!$R$3:$R$40))/STDEV(RawData!$R$3:$R$40)) -> 4.8261269 | S10: =-1*((RawData!S9-AVERAGE(RawData!$S$3:$S$40))/STDEV(RawData!$S$3:$S$40)) -> 0.33845396 | T10: =-1*((AbsValues!C9-AVERAGE(AbsValues!$C$3:$C$40))/STDEV(AbsValues!$C$3:$C$40)) -> -0.52339323 | U10: =-1*((RawData!U9-AVERAGE(RawData!$U$3:$U$40))/STDEV(RawData!$U$3:$U$40)) -> 0.37657581 | V10: =-1*((RawData!V9-AVERAGE(RawData!$V$3:$V$40))/STDEV(RawData!$V$3:$V$40)) -> 0.41333197 | W10: =-1*((RawData!W9-AVERAGE(RawData!$W$3:$W$40))/STDEV(RawData!$W$3:$W$40)) -> 0.06784786 | X10: =-1*((RawData!X9-AVERAGE(RawData!$X$3:$X$40))/STDEV(RawData!$X$3:$X$40)) -> 1.1513215 | Y10: =((RawData!Y9-AVERAGE(RawData!$Y$3:$Y$40))/STDEV(RawData!$Y$3:$Y$40)) -> -1.3685787 | Z10: =((RawData!Z9-AVERAGE(RawData!$Z$3:$Z$40))/STDEV(RawData!$Z$3:$Z$40)) -> 0.18465614 | AA10: =-1*((RawData!AA9-AVERAGE(RawData!$AA$3:$AA$40))/STDEV(RawData!$AA$3:$AA$40)) -> 0.72433424 | AB10: =-1*((RawData!AB9-AVERAGE(RawData!$AB$3:$AB$40))/STDEV(RawData!$AB$3:$AB$40)) -> -2.6162858 | AC10: =-1*((RawData!AC9-AVERAGE(RawData!$AC$3:$AC$40))/STDEV(RawData!$AC$3:$AC$40)) -> -0.6703676 | AD10: =-1*((RawData!AD9-AVERAGE(RawData!$AD$3:$AD$40))/STDEV(RawData!$AD$3:$AD$40)) -> -0.42727718 | AE10: =-1*((RawData!AE9-AVERAGE(RawData!$AE$3:$AE$40))/STDEV(RawData!$AE$3:$AE$40)) -> 1.0401304 | AF10: =-1*((RawData!AF9-AVERAGE(RawData!$AF$3:$AF$40))/STDEV(RawData!$AF$3:$AF$40)) -> -1.6511559 | AG10: =-1*((RawData!AG9-AVERAGE(RawData!$AG$3:$AG$40))/STDEV(RawData!$AG$3:$AG$40)) -> -1.2218766 | AH10: =((RawData!AH9-AVERAGE(RawData!$AH$3:$AH$40))/STDEV(RawData!$AH$3:$AH$40)) -> -3.3615451 | AI10: =((RawData!AI9-AVERAGE(RawData!$AI$3:$AI$40))/STDEV(RawData!$AI$3:$AI$40)) -> -1.9852328 | AJ10: =-1*((RawData!AJ9-AVERAGE(RawData!$AJ$3:$AJ$40))/STDEV(RawData!$AJ$3:$AJ$40)) -> 0.98675438 | AK10: =-1*((RawData!AK9-AVERAGE(RawData!$AK$3:$AK$40))/STDEV(RawData!$AK$3:$AK$40)) -> 0.048339408 | AL10: =-1*((RawData!AL9-AVERAGE(RawData!$AL$3:$AL$40))/STDEV(RawData!$AL$3:$AL$40)) -> -0.45173693 | AM10: =-1*((RawData!AM9-AVERAGE(RawData!$AM$3:$AM$40))/STDEV(RawData!$AM$3:$AM$40)) -> -0.24215868 | AN10: =((RawData!AN9-AVERAGE(RawData!$AN$3:$AN$40))/STDEV(RawData!$AN$3:$AN$40)) -> -2.3245686 | AO10: =-1*((RawData!AO9-AVERAGE(RawData!$AO$3:$AO$40))/STDEV(RawData!$AO$3:$AO$40)) -> -1.3355779 | AP10: =-1*((RawData!AP9-AVERAGE(RawData!$AP$3:$AP$40))/STDEV(RawData!$AP$3:$AP$40)) -> 1.5588062 | AQ10: =-1*((RawData!AQ9-AVERAGE(RawData!$AQ$3:$AQ$40))/STDEV(RawData!$AQ$3:$AQ$40)) -> 1.5732719
A11: =RawData!A10 -> Costa Rica | B11: =-1*((RawData!B10-AVERAGE(RawData!$B$3:$B$40))/STDEV(RawData!$B$3:$B$40)) -> -1.0631397 | C11: =((RawData!C10-AVERAGE(RawData!$C$3:$C$40))/STDEV(RawData!$C$3:$C$40)) -> -0.24662998 | D11: =((RawData!D10-AVERAGE(RawData!$D$3:$D$40))/STDEV(RawData!$D$3:$D$40)) -> -1.1101589 | E11: =((RawData!E10-AVERAGE(RawData!$E$3:$E$40))/STDEV(RawData!$E$3:$E$40)) -> -0.42248502 | F11: =((RawData!F10-AVERAGE(RawData!$F$3:$F$40))/STDEV(RawData!$F$3:$F$40)) -> -1.1366879 | G11: =((RawData!G10-AVERAGE(RawData!$G$3:$G$40))/STDEV(RawData!$G$3:$G$40)) -> -0.16428036 | H11: =((RawData!H10-AVERAGE(RawData!$H$3:$H$40))/STDEV(RawData!$H$3:$H$40)) -> -0.2662561 | I11: =((RawData!I10-AVERAGE(RawData!$I$3:$I$40))/STDEV(RawData!$I$3:$I$40)) -> -0.38409362 | J11: =-1*((RawData!J10-AVERAGE(RawData!$J$3:$J$40))/STDEV(RawData!$J$3:$J$40)) -> 0.9361174 | K11: =-1*((RawData!K10-AVERAGE(RawData!$K$3:$K$40))/STDEV(RawData!$K$3:$K$40)) -> 1.574608 | L11: =-1*((RawData!L10-AVERAGE(RawData!$L$3:$L$40))/STDEV(RawData!$L$3:$L$40)) -> 0.6703676 | M11: =-1*((RawData!M10-AVERAGE(RawData!$M$3:$M$40))/STDEV(RawData!$M$3:$M$40)) -> -2.2395907 | N11: =-1*((RawData!N10-AVERAGE(RawData!$N$3:$N$40))/STDEV(RawData!$N$3:$N$40)) -> 0.33845396 | O11: =-1*((AbsValues!B10-AVERAGE(AbsValues!$B$3:$B$40))/STDEV(AbsValues!$B$3:$B$40)) -> -1.7970792 | P11: =-1*((RawData!P10-AVERAGE(RawData!$P$3:$P$40))/STDEV(RawData!$P$3:$P$40)) -> 1.34831 | Q11: =-1*((RawData!Q10-AVERAGE(RawData!$Q$3:$Q$40))/STDEV(RawData!$Q$3:$Q$40)) -> 0.023567445 | R11: =-1*((RawData!R10-AVERAGE(RawData!$R$3:$R$40))/STDEV(RawData!$R$3:$R$40)) -> 0.66356595 | S11: =-1*((RawData!S10-AVERAGE(RawData!$S$3:$S$40))/STDEV(RawData!$S$3:$S$40)) -> 0.33845396 | T11: =-1*((AbsValues!C10-AVERAGE(AbsValues!$C$3:$C$40))/STDEV(AbsValues!$C$3:$C$40)) -> -3.860518 | U11: =-1*((RawData!U10-AVERAGE(RawData!$U$3:$U$40))/STDEV(RawData!$U$3:$U$40)) -> 0.37657581 | V11: =-1*((RawData!V10-AVERAGE(RawData!$V$3:$V$40))/STDEV(RawData!$V$3:$V$40)) -> 0.85082825 | W11: =-1*((RawData!W10-AVERAGE(RawData!$W$3:$W$40))/STDEV(RawData!$W$3:$W$40)) -> 1.2222741 | X11: =-1*((RawData!X10-AVERAGE(RawData!$X$3:$X$40))/STDEV(RawData!$X$3:$X$40)) -> 1.1513215 | Y11: =((RawData!Y10-AVERAGE(RawData!$Y$3:$Y$40))/STDEV(RawData!$Y$3:$Y$40)) -> -0.43150517 | Z11: =((RawData!Z10-AVERAGE(RawData!$Z$3:$Z$40))/STDEV(RawData!$Z$3:$Z$40)) -> 0.18465614 | AA11: =-1*((RawData!AA10-AVERAGE(RawData!$AA$3:$AA$40))/STDEV(RawData!$AA$3:$AA$40)) -> 0.72368386 | AB11: =-1*((RawData!AB10-AVERAGE(RawData!$AB$3:$AB$40))/STDEV(RawData!$AB$3:$AB$40)) -> 0.44275606 | AC11: =-1*((RawData!AC10-AVERAGE(RawData!$AC$3:$AC$40))/STDEV(RawData!$AC$3:$AC$40)) -> 1.4524631 | AD11: =-1*((RawData!AD10-AVERAGE(RawData!$AD$3:$AD$40))/STDEV(RawData!$AD$3:$AD$40)) -> -0.42727718 | AE11: =-1*((RawData!AE10-AVERAGE(RawData!$AE$3:$AE$40))/STDEV(RawData!$AE$3:$AE$40)) -> -0.9361174 | AF11: =-1*((RawData!AF10-AVERAGE(RawData!$AF$3:$AF$40))/STDEV(RawData!$AF$3:$AF$40)) -> 0.58969853 | AG11: =-1*((RawData!AG10-AVERAGE(RawData!$AG$3:$AG$40))/STDEV(RawData!$AG$3:$AG$40)) -> -1.2218766 | AH11: =((RawData!AH10-AVERAGE(RawData!$AH$3:$AH$40))/STDEV(RawData!$AH$3:$AH$40)) -> 0.32819245 | AI11: =((RawData!AI10-AVERAGE(RawData!$AI$3:$AI$40))/STDEV(RawData!$AI$3:$AI$40)) -> 0.55436816 | AJ11: =-1*((RawData!AJ10-AVERAGE(RawData!$AJ$3:$AJ$40))/STDEV(RawData!$AJ$3:$AJ$40)) -> 0.98675438 | AK11: =-1*((RawData!AK10-AVERAGE(RawData!$AK$3:$AK$40))/STDEV(RawData!$AK$3:$AK$40)) -> 0.55036113 | AL11: =-1*((RawData!AL10-AVERAGE(RawData!$AL$3:$AL$40))/STDEV(RawData!$AL$3:$AL$40)) -> -0.015120709 | AM11: =-1*((RawData!AM10-AVERAGE(RawData!$AM$3:$AM$40))/STDEV(RawData!$AM$3:$AM$40)) -> -0.74635186 | AN11: =((RawData!AN10-AVERAGE(RawData!$AN$3:$AN$40))/STDEV(RawData!$AN$3:$AN$40)) -> -2.7001367 | AO11: =-1*((RawData!AO10-AVERAGE(RawData!$AO$3:$AO$40))/STDEV(RawData!$AO$3:$AO$40)) -> 2.5684191 | AP11: =-1*((RawData!AP10-AVERAGE(RawData!$AP$3:$AP$40))/STDEV(RawData!$AP$3:$AP$40)) -> -0.48376743 | AQ11: =-1*((RawData!AQ10-AVERAGE(RawData!$AQ$3:$AQ$40))/STDEV(RawData!$AQ$3:$AQ$40)) -> 1.5732719
A12: =RawData!A11 -> Czech Republic | B12: =-1*((RawData!B11-AVERAGE(RawData!$B$3:$B$40))/STDEV(RawData!$B$3:$B$40)) -> 0.58631398 | C12: =((RawData!C11-AVERAGE(RawData!$C$3:$C$40))/STDEV(RawData!$C$3:$C$40)) -> -0.15800644 | D12: =((RawData!D11-AVERAGE(RawData!$D$3:$D$40))/STDEV(RawData!$D$3:$D$40)) -> -1.0594133 | E12: =((RawData!E11-AVERAGE(RawData!$E$3:$E$40))/STDEV(RawData!$E$3:$E$40)) -> 0.2103632 | F12: =((RawData!F11-AVERAGE(RawData!$F$3:$F$40))/STDEV(RawData!$F$3:$F$40)) -> 0.23002689 | G12: =((RawData!G11-AVERAGE(RawData!$G$3:$G$40))/STDEV(RawData!$G$3:$G$40)) -> 0.42027513 | H12: =((RawData!H11-AVERAGE(RawData!$H$3:$H$40))/STDEV(RawData!$H$3:$H$40)) -> -0.2662561 | I12: =((RawData!I11-AVERAGE(RawData!$I$3:$I$40))/STDEV(RawData!$I$3:$I$40)) -> -0.38409362 | J12: =-1*((RawData!J11-AVERAGE(RawData!$J$3:$J$40))/STDEV(RawData!$J$3:$J$40)) -> 0.9361174 | K12: =-1*((RawData!K11-AVERAGE(RawData!$K$3:$K$40))/STDEV(RawData!$K$3:$K$40)) -> -0.39509184 | L12: =-1*((RawData!L11-AVERAGE(RawData!$L$3:$L$40))/STDEV(RawData!$L$3:$L$40)) -> 0.6703676 | M12: =-1*((RawData!M11-AVERAGE(RawData!$M$3:$M$40))/STDEV(RawData!$M$3:$M$40)) -> 0.62106297 | N12: =-1*((RawData!N11-AVERAGE(RawData!$N$3:$N$40))/STDEV(RawData!$N$3:$N$40)) -> 0.33845396 | O12: =-1*((AbsValues!B11-AVERAGE(AbsValues!$B$3:$B$40))/STDEV(AbsValues!$B$3:$B$40)) -> 0.59391264 | P12: =-1*((RawData!P11-AVERAGE(RawData!$P$3:$P$40))/STDEV(RawData!$P$3:$P$40)) -> 1.2423429 | Q12: =-1*((RawData!Q11-AVERAGE(RawData!$Q$3:$Q$40))/STDEV(RawData!$Q$3:$Q$40)) -> 0.44866878 | R12: =-1*((RawData!R11-AVERAGE(RawData!$R$3:$R$40))/STDEV(RawData!$R$3:$R$40)) -> 0.50134373 | S12: =-1*((RawData!S11-AVERAGE(RawData!$S$3:$S$40))/STDEV(RawData!$S$3:$S$40)) -> 0.33845396 | T12: =-1*((AbsValues!C11-AVERAGE(AbsValues!$C$3:$C$40))/STDEV(AbsValues!$C$3:$C$40)) -> 0.32073762 | U12: =-1*((RawData!U11-AVERAGE(RawData!$U$3:$U$40))/STDEV(RawData!$U$3:$U$40)) -> -0.22846116 | V12: =-1*((RawData!V11-AVERAGE(RawData!$V$3:$V$40))/STDEV(RawData!$V$3:$V$40)) -> 0.15083421 | W12: =-1*((RawData!W11-AVERAGE(RawData!$W$3:$W$40))/STDEV(RawData!$W$3:$W$40)) -> -0.3169609 | X12: =-1*((RawData!X11-AVERAGE(RawData!$X$3:$X$40))/STDEV(RawData!$X$3:$X$40)) -> -2.0206751 | Y12: =((RawData!Y11-AVERAGE(RawData!$Y$3:$Y$40))/STDEV(RawData!$Y$3:$Y$40)) -> 0.36085131 | Z12: =((RawData!Z11-AVERAGE(RawData!$Z$3:$Z$40))/STDEV(RawData!$Z$3:$Z$40)) -> 0.18465614 | AA12: =-1*((RawData!AA11-AVERAGE(RawData!$AA$3:$AA$40))/STDEV(RawData!$AA$3:$AA$40)) -> 0.71688453 | AB12: =-1*((RawData!AB11-AVERAGE(RawData!$AB$3:$AB$40))/STDEV(RawData!$AB$3:$AB$40)) -> 0.44275606 | AC12: =-1*((RawData!AC11-AVERAGE(RawData!$AC$3:$AC$40))/STDEV(RawData!$AC$3:$AC$40)) -> -0.6703676 | AD12: =-1*((RawData!AD11-AVERAGE(RawData!$AD$3:$AD$40))/STDEV(RawData!$AD$3:$AD$40)) -> 2.2788116 | AE12: =-1*((RawData!AE11-AVERAGE(RawData!$AE$3:$AE$40))/STDEV(RawData!$AE$3:$AE$40)) -> 1.0401304 | AF12: =-1*((RawData!AF11-AVERAGE(RawData!$AF$3:$AF$40))/STDEV(RawData!$AF$3:$AF$40)) -> 0.58969853 | AG12: =-1*((RawData!AG11-AVERAGE(RawData!$AG$3:$AG$40))/STDEV(RawData!$AG$3:$AG$40)) -> 0.79687605 | AH12: =((RawData!AH11-AVERAGE(RawData!$AH$3:$AH$40))/STDEV(RawData!$AH$3:$AH$40)) -> 0.32819245 | AI12: =((RawData!AI11-AVERAGE(RawData!$AI$3:$AI$40))/STDEV(RawData!$AI$3:$AI$40)) -> 0.55436816 | AJ12: =-1*((RawData!AJ11-AVERAGE(RawData!$AJ$3:$AJ$40))/STDEV(RawData!$AJ$3:$AJ$40)) -> -0.98675438 | AK12: =-1*((RawData!AK11-AVERAGE(RawData!$AK$3:$AK$40))/STDEV(RawData!$AK$3:$AK$40)) -> 0.55036113 | AL12: =-1*((RawData!AL11-AVERAGE(RawData!$AL$3:$AL$40))/STDEV(RawData!$AL$3:$AL$40)) -> -0.015120709 | AM12: =-1*((RawData!AM11-AVERAGE(RawData!$AM$3:$AM$40))/STDEV(RawData!$AM$3:$AM$40)) -> 0.2620345 | AN12: =((RawData!AN11-AVERAGE(RawData!$AN$3:$AN$40))/STDEV(RawData!$AN$3:$AN$40)) -> 0.83020307 | AO12: =-1*((RawData!AO11-AVERAGE(RawData!$AO$3:$AO$40))/STDEV(RawData!$AO$3:$AO$40)) -> 0.61642058 | AP12: =-1*((RawData!AP11-AVERAGE(RawData!$AP$3:$AP$40))/STDEV(RawData!$AP$3:$AP$40)) -> -0.48376743 | AQ12: =-1*((RawData!AQ11-AVERAGE(RawData!$AQ$3:$AQ$40))/STDEV(RawData!$AQ$3:$AQ$40)) -> -0.68274065
A13: =RawData!A12 -> Germany | B13: =-1*((RawData!B12-AVERAGE(RawData!$B$3:$B$40))/STDEV(RawData!$B$3:$B$40)) -> -1.0738542 | C13: =((RawData!C12-AVERAGE(RawData!$C$3:$C$40))/STDEV(RawData!$C$3:$C$40)) -> -0.15800644 | D13: =((RawData!D12-AVERAGE(RawData!$D$3:$D$40))/STDEV(RawData!$D$3:$D$40)) -> 0.58981677 | E13: =((RawData!E12-AVERAGE(RawData!$E$3:$E$40))/STDEV(RawData!$E$3:$E$40)) -> 0.24279096 | F13: =((RawData!F12-AVERAGE(RawData!$F$3:$F$40))/STDEV(RawData!$F$3:$F$40)) -> -0.55513491 | G13: =((RawData!G12-AVERAGE(RawData!$G$3:$G$40))/STDEV(RawData!$G$3:$G$40)) -> 0.58161067 | H13: =((RawData!H12-AVERAGE(RawData!$H$3:$H$40))/STDEV(RawData!$H$3:$H$40)) -> 1.1791342 | I13: =((RawData!I12-AVERAGE(RawData!$I$3:$I$40))/STDEV(RawData!$I$3:$I$40)) -> -0.38409362 | J13: =-1*((RawData!J12-AVERAGE(RawData!$J$3:$J$40))/STDEV(RawData!$J$3:$J$40)) -> 0.9361174 | K13: =-1*((RawData!K12-AVERAGE(RawData!$K$3:$K$40))/STDEV(RawData!$K$3:$K$40)) -> -0.89845957 | L13: =-1*((RawData!L12-AVERAGE(RawData!$L$3:$L$40))/STDEV(RawData!$L$3:$L$40)) -> 0.6703676 | M13: =-1*((RawData!M12-AVERAGE(RawData!$M$3:$M$40))/STDEV(RawData!$M$3:$M$40)) -> 0.62106297 | N13: =-1*((RawData!N12-AVERAGE(RawData!$N$3:$N$40))/STDEV(RawData!$N$3:$N$40)) -> -2.8768587 | O13: =-1*((AbsValues!B12-AVERAGE(AbsValues!$B$3:$B$40))/STDEV(AbsValues!$B$3:$B$40)) -> 0.59391264 | P13: =-1*((RawData!P12-AVERAGE(RawData!$P$3:$P$40))/STDEV(RawData!$P$3:$P$40)) -> -0.14304859 | Q13: =-1*((RawData!Q12-AVERAGE(RawData!$Q$3:$Q$40))/STDEV(RawData!$Q$3:$Q$40)) -> 0.25936472 | R13: =-1*((RawData!R12-AVERAGE(RawData!$R$3:$R$40))/STDEV(RawData!$R$3:$R$40)) -> 0.6745694 | S13: =-1*((RawData!S12-AVERAGE(RawData!$S$3:$S$40))/STDEV(RawData!$S$3:$S$40)) -> -2.8768587 | T13: =-1*((AbsValues!C12-AVERAGE(AbsValues!$C$3:$C$40))/STDEV(AbsValues!$C$3:$C$40)) -> 0.32073762 | U13: =-1*((RawData!U12-AVERAGE(RawData!$U$3:$U$40))/STDEV(RawData!$U$3:$U$40)) -> -0.48371114 | V13: =-1*((RawData!V12-AVERAGE(RawData!$V$3:$V$40))/STDEV(RawData!$V$3:$V$40)) -> -0.14447578 | W13: =-1*((RawData!W12-AVERAGE(RawData!$W$3:$W$40))/STDEV(RawData!$W$3:$W$40)) -> 0.06784786 | X13: =-1*((RawData!X12-AVERAGE(RawData!$X$3:$X$40))/STDEV(RawData!$X$3:$X$40)) -> 0.43073313 | Y13: =((RawData!Y12-AVERAGE(RawData!$Y$3:$Y$40))/STDEV(RawData!$Y$3:$Y$40)) -> -0.16183976 | Z13: =((RawData!Z12-AVERAGE(RawData!$Z$3:$Z$40))/STDEV(RawData!$Z$3:$Z$40)) -> 0.18465614 | AA13: =-1*((RawData!AA12-AVERAGE(RawData!$AA$3:$AA$40))/STDEV(RawData!$AA$3:$AA$40)) -> 0.30723261 | AB13: =-1*((RawData!AB12-AVERAGE(RawData!$AB$3:$AB$40))/STDEV(RawData!$AB$3:$AB$40)) -> 0.44275606 | AC13: =-1*((RawData!AC12-AVERAGE(RawData!$AC$3:$AC$40))/STDEV(RawData!$AC$3:$AC$40)) -> -0.6703676 | AD13: =-1*((RawData!AD12-AVERAGE(RawData!$AD$3:$AD$40))/STDEV(RawData!$AD$3:$AD$40)) -> -0.42727718 | AE13: =-1*((RawData!AE12-AVERAGE(RawData!$AE$3:$AE$40))/STDEV(RawData!$AE$3:$AE$40)) -> 1.0401304 | AF13: =-1*((RawData!AF12-AVERAGE(RawData!$AF$3:$AF$40))/STDEV(RawData!$AF$3:$AF$40)) -> 0.58969853 | AG13: =-1*((RawData!AG12-AVERAGE(RawData!$AG$3:$AG$40))/STDEV(RawData!$AG$3:$AG$40)) -> 0.79687605 | AH13: =((RawData!AH12-AVERAGE(RawData!$AH$3:$AH$40))/STDEV(RawData!$AH$3:$AH$40)) -> 0.14370557 | AI13: =((RawData!AI12-AVERAGE(RawData!$AI$3:$AI$40))/STDEV(RawData!$AI$3:$AI$40)) -> 0.42738811 | AJ13: =-1*((RawData!AJ12-AVERAGE(RawData!$AJ$3:$AJ$40))/STDEV(RawData!$AJ$3:$AJ$40)) -> 0.98675438 | AK13: =-1*((RawData!AK12-AVERAGE(RawData!$AK$3:$AK$40))/STDEV(RawData!$AK$3:$AK$40)) -> -0.59173829 | AL13: =-1*((RawData!AL12-AVERAGE(RawData!$AL$3:$AL$40))/STDEV(RawData!$AL$3:$AL$40)) -> 1.2947279 | AM13: =-1*((RawData!AM12-AVERAGE(RawData!$AM$3:$AM$40))/STDEV(RawData!$AM$3:$AM$40)) -> 0.17884263 | AN13: =((RawData!AN12-AVERAGE(RawData!$AN$3:$AN$40))/STDEV(RawData!$AN$3:$AN$40)) -> 0.71753265 | AO13: =-1*((RawData!AO12-AVERAGE(RawData!$AO$3:$AO$40))/STDEV(RawData!$AO$3:$AO$40)) -> 0.61642058 | AP13: =-1*((RawData!AP12-AVERAGE(RawData!$AP$3:$AP$40))/STDEV(RawData!$AP$3:$AP$40)) -> -0.48376743 | AQ13: =-1*((RawData!AQ12-AVERAGE(RawData!$AQ$3:$AQ$40))/STDEV(RawData!$AQ$3:$AQ$40)) -> -0.68274065
A14: =RawData!A13 -> Denmark | B14: =-1*((RawData!B13-AVERAGE(RawData!$B$3:$B$40))/STDEV(RawData!$B$3:$B$40)) -> 0.40304135 | C14: =((RawData!C13-AVERAGE(RawData!$C$3:$C$40))/STDEV(RawData!$C$3:$C$40)) -> -0.24662998 | D14: =((RawData!D13-AVERAGE(RawData!$D$3:$D$40))/STDEV(RawData!$D$3:$D$40)) -> 0.33608906 | E14: =((RawData!E13-AVERAGE(RawData!$E$3:$E$40))/STDEV(RawData!$E$3:$E$40)) -> -0.36751786 | F14: =((RawData!F13-AVERAGE(RawData!$F$3:$F$40))/STDEV(RawData!$F$3:$F$40)) -> -0.55513491 | G14: =((RawData!G13-AVERAGE(RawData!$G$3:$G$40))/STDEV(RawData!$G$3:$G$40)) -> 0.26252277 | H14: =((RawData!H13-AVERAGE(RawData!$H$3:$H$40))/STDEV(RawData!$H$3:$H$40)) -> -1.7116464 | I14: =((RawData!I13-AVERAGE(RawData!$I$3:$I$40))/STDEV(RawData!$I$3:$I$40)) -> -0.38409362 | J14: =-1*((RawData!J13-AVERAGE(RawData!$J$3:$J$40))/STDEV(RawData!$J$3:$J$40)) -> 0.9361174 | K14: =-1*((RawData!K13-AVERAGE(RawData!$K$3:$K$40))/STDEV(RawData!$K$3:$K$40)) -> 1.3119813 | L14: =-1*((RawData!L13-AVERAGE(RawData!$L$3:$L$40))/STDEV(RawData!$L$3:$L$40)) -> -1.4524631 | M14: =-1*((RawData!M13-AVERAGE(RawData!$M$3:$M$40))/STDEV(RawData!$M$3:$M$40)) -> 0.62106297 | N14: =-1*((RawData!N13-AVERAGE(RawData!$N$3:$N$40))/STDEV(RawData!$N$3:$N$40)) -> 0.33845396 | O14: =-1*((AbsValues!B13-AVERAGE(AbsValues!$B$3:$B$40))/STDEV(AbsValues!$B$3:$B$40)) -> -0.42594905 | P14: =-1*((RawData!P13-AVERAGE(RawData!$P$3:$P$40))/STDEV(RawData!$P$3:$P$40)) -> -1.0500792 | Q14: =-1*((RawData!Q13-AVERAGE(RawData!$Q$3:$Q$40))/STDEV(RawData!$Q$3:$Q$40)) -> 0.62163709 | R14: =-1*((RawData!R13-AVERAGE(RawData!$R$3:$R$40))/STDEV(RawData!$R$3:$R$40)) -> 0.049027454 | S14: =-1*((RawData!S13-AVERAGE(RawData!$S$3:$S$40))/STDEV(RawData!$S$3:$S$40)) -> 0.33845396 | T14: =-1*((AbsValues!C13-AVERAGE(AbsValues!$C$3:$C$40))/STDEV(AbsValues!$C$3:$C$40)) -> 0.32073762 | U14: =-1*((RawData!U13-AVERAGE(RawData!$U$3:$U$40))/STDEV(RawData!$U$3:$U$40)) -> -1.665424 | V14: =-1*((RawData!V13-AVERAGE(RawData!$V$3:$V$40))/STDEV(RawData!$V$3:$V$40)) -> -1.5116517 | W14: =-1*((RawData!W13-AVERAGE(RawData!$W$3:$W$40))/STDEV(RawData!$W$3:$W$40)) -> -1.0865784 | X14: =-1*((RawData!X13-AVERAGE(RawData!$X$3:$X$40))/STDEV(RawData!$X$3:$X$40)) -> 0.98637605 | Y14: =((RawData!Y13-AVERAGE(RawData!$Y$3:$Y$40))/STDEV(RawData!$Y$3:$Y$40)) -> 0.57772646 | Z14: =((RawData!Z13-AVERAGE(RawData!$Z$3:$Z$40))/STDEV(RawData!$Z$3:$Z$40)) -> 0.18465614 | AA14: =-1*((RawData!AA13-AVERAGE(RawData!$AA$3:$AA$40))/STDEV(RawData!$AA$3:$AA$40)) -> 0.52790204 | AB14: =-1*((RawData!AB13-AVERAGE(RawData!$AB$3:$AB$40))/STDEV(RawData!$AB$3:$AB$40)) -> 0.44275606 | AC14: =-1*((RawData!AC13-AVERAGE(RawData!$AC$3:$AC$40))/STDEV(RawData!$AC$3:$AC$40)) -> -0.6703676 | AD14: =-1*((RawData!AD13-AVERAGE(RawData!$AD$3:$AD$40))/STDEV(RawData!$AD$3:$AD$40)) -> -0.42727718 | AE14: =-1*((RawData!AE13-AVERAGE(RawData!$AE$3:$AE$40))/STDEV(RawData!$AE$3:$AE$40)) -> 1.0401304 | AF14: =-1*((RawData!AF13-AVERAGE(RawData!$AF$3:$AF$40))/STDEV(RawData!$AF$3:$AF$40)) -> 0.58969853 | AG14: =-1*((RawData!AG13-AVERAGE(RawData!$AG$3:$AG$40))/STDEV(RawData!$AG$3:$AG$40)) -> 0.79687605 | AH14: =((RawData!AH13-AVERAGE(RawData!$AH$3:$AH$40))/STDEV(RawData!$AH$3:$AH$40)) -> 0.32819245 | AI14: =((RawData!AI13-AVERAGE(RawData!$AI$3:$AI$40))/STDEV(RawData!$AI$3:$AI$40)) -> 0.55436816 | AJ14: =-1*((RawData!AJ13-AVERAGE(RawData!$AJ$3:$AJ$40))/STDEV(RawData!$AJ$3:$AJ$40)) -> -0.98675438 | AK14: =-1*((RawData!AK13-AVERAGE(RawData!$AK$3:$AK$40))/STDEV(RawData!$AK$3:$AK$40)) -> -0.65449101 | AL14: =-1*((RawData!AL13-AVERAGE(RawData!$AL$3:$AL$40))/STDEV(RawData!$AL$3:$AL$40)) -> -0.62638341 | AM14: =-1*((RawData!AM13-AVERAGE(RawData!$AM$3:$AM$40))/STDEV(RawData!$AM$3:$AM$40)) -> -0.44383595 | AN14: =((RawData!AN13-AVERAGE(RawData!$AN$3:$AN$40))/STDEV(RawData!$AN$3:$AN$40)) -> 0.041510154 | AO14: =-1*((RawData!AO13-AVERAGE(RawData!$AO$3:$AO$40))/STDEV(RawData!$AO$3:$AO$40)) -> -1.3355779 | AP14: =-1*((RawData!AP13-AVERAGE(RawData!$AP$3:$AP$40))/STDEV(RawData!$AP$3:$AP$40)) -> -0.48376743 | AQ14: =-1*((RawData!AQ13-AVERAGE(RawData!$AQ$3:$AQ$40))/STDEV(RawData!$AQ$3:$AQ$40)) -> -0.68274065
